Traceback (most recent call last):
  File "/home/haoting/.virtualenvs/connectome_confounds/lib/python3.8/site-packages/jupyter_cache/executors/utils.py", line 51, in single_nb_execution
    executenb(
  File "/home/haoting/.virtualenvs/connectome_confounds/lib/python3.8/site-packages/nbclient/client.py", line 1093, in execute
    return NotebookClient(nb=nb, resources=resources, km=km, **kwargs).execute()
  File "/home/haoting/.virtualenvs/connectome_confounds/lib/python3.8/site-packages/nbclient/util.py", line 84, in wrapped
    return just_run(coro(*args, **kwargs))
  File "/home/haoting/.virtualenvs/connectome_confounds/lib/python3.8/site-packages/nbclient/util.py", line 62, in just_run
    return loop.run_until_complete(coro)
  File "/usr/lib/python3.8/asyncio/base_events.py", line 616, in run_until_complete
    return future.result()
  File "/home/haoting/.virtualenvs/connectome_confounds/lib/python3.8/site-packages/nbclient/client.py", line 559, in async_execute
    await self.async_execute_cell(
  File "/home/haoting/.virtualenvs/connectome_confounds/lib/python3.8/site-packages/nbclient/client.py", line 854, in async_execute_cell
    self._check_raise_for_error(cell, exec_reply)
  File "/home/haoting/.virtualenvs/connectome_confounds/lib/python3.8/site-packages/nbclient/client.py", line 756, in _check_raise_for_error
    raise CellExecutionError.from_cell_and_msg(cell, exec_reply_content)
nbclient.exceptions.CellExecutionError: An error occurred while executing the following cell:
------------------
import warnings
warnings.filterwarnings("ignore")
import pandas as pd
from fmriprep_denoise.visualization import tables
desc = tabels.lazy_report('ds000228')
desc
------------------

[0;31m---------------------------------------------------------------------------[0m
[0;31mNameError[0m                                 Traceback (most recent call last)
[0;32m/tmp/ipykernel_126346/3269205586.py[0m in [0;36m<module>[0;34m[0m
[1;32m      3[0m [0;32mimport[0m [0mpandas[0m [0;32mas[0m [0mpd[0m[0;34m[0m[0;34m[0m[0m
[1;32m      4[0m [0;32mfrom[0m [0mfmriprep_denoise[0m[0;34m.[0m[0mvisualization[0m [0;32mimport[0m [0mtables[0m[0;34m[0m[0;34m[0m[0m
[0;32m----> 5[0;31m [0mdesc[0m [0;34m=[0m [0mtabels[0m[0;34m.[0m[0mlazy_report[0m[0;34m([0m[0;34m'ds000228'[0m[0;34m)[0m[0;34m[0m[0;34m[0m[0m
[0m[1;32m      6[0m [0mdesc[0m[0;34m[0m[0;34m[0m[0m

[0;31mNameError[0m: name 'tabels' is not defined
NameError: name 'tabels' is not defined

