Traceback (most recent call last):
  File "/home/haoting/.virtualenvs/fmriprep-denoise-benchmark/lib/python3.7/site-packages/jupyter_cache/executors/utils.py", line 56, in single_nb_execution
    record_timing=False,
  File "/home/haoting/.virtualenvs/fmriprep-denoise-benchmark/lib/python3.7/site-packages/nbclient/client.py", line 1204, in execute
    return NotebookClient(nb=nb, resources=resources, km=km, **kwargs).execute()
  File "/home/haoting/.virtualenvs/fmriprep-denoise-benchmark/lib/python3.7/site-packages/nbclient/util.py", line 84, in wrapped
    return just_run(coro(*args, **kwargs))
  File "/home/haoting/.virtualenvs/fmriprep-denoise-benchmark/lib/python3.7/site-packages/nbclient/util.py", line 62, in just_run
    return loop.run_until_complete(coro)
  File "/home/haoting/.pyenv/versions/3.7.14/lib/python3.7/asyncio/base_events.py", line 587, in run_until_complete
    return future.result()
  File "/home/haoting/.virtualenvs/fmriprep-denoise-benchmark/lib/python3.7/site-packages/nbclient/client.py", line 664, in async_execute
    cell, index, execution_count=self.code_cells_executed + 1
  File "/home/haoting/.virtualenvs/fmriprep-denoise-benchmark/lib/python3.7/site-packages/nbclient/client.py", line 965, in async_execute_cell
    await self._check_raise_for_error(cell, cell_index, exec_reply)
  File "/home/haoting/.virtualenvs/fmriprep-denoise-benchmark/lib/python3.7/site-packages/nbclient/client.py", line 862, in _check_raise_for_error
    raise CellExecutionError.from_cell_and_msg(cell, exec_reply_content)
nbclient.exceptions.CellExecutionError: An error occurred while executing the following cell:
------------------
fig = plt.figure(figsize=(11, 5))
fig.title('Similarity of the denoised connectomes')

axes = fig.subplots(1, 2)
for ds, subfig in zip(datasets, axes):
    cc = pd.read_csv(path_root / ds / f'fmriprep-20.2.1lts/dataset-{ds}_atlas-mist_nroi-ROI_connectome.tsv', sep='\t', index_col=0)
    g = plot_matrix(cc.corr().values, labels=list(cc.columns), colorbar=False, axes=subfig, 
                reorder='complete', vmax=1, vmin=0.7)
------------------

[0;31m---------------------------------------------------------------------------[0m
[0;31mAttributeError[0m                            Traceback (most recent call last)
[0;32m/tmp/ipykernel_25782/1965003236.py[0m in [0;36m<module>[0;34m[0m
[1;32m      1[0m [0mfig[0m [0;34m=[0m [0mplt[0m[0;34m.[0m[0mfigure[0m[0;34m([0m[0mfigsize[0m[0;34m=[0m[0;34m([0m[0;36m11[0m[0;34m,[0m [0;36m5[0m[0;34m)[0m[0;34m)[0m[0;34m[0m[0;34m[0m[0m
[0;32m----> 2[0;31m [0mfig[0m[0;34m.[0m[0mtitle[0m[0;34m([0m[0;34m'Similarity of the denoised connectomes'[0m[0;34m)[0m[0;34m[0m[0;34m[0m[0m
[0m[1;32m      3[0m [0;34m[0m[0m
[1;32m      4[0m [0maxes[0m [0;34m=[0m [0mfig[0m[0;34m.[0m[0msubplots[0m[0;34m([0m[0;36m1[0m[0;34m,[0m [0;36m2[0m[0;34m)[0m[0;34m[0m[0;34m[0m[0m
[1;32m      5[0m [0;32mfor[0m [0mds[0m[0;34m,[0m [0msubfig[0m [0;32min[0m [0mzip[0m[0;34m([0m[0mdatasets[0m[0;34m,[0m [0maxes[0m[0;34m)[0m[0;34m:[0m[0;34m[0m[0;34m[0m[0m

[0;31mAttributeError[0m: 'Figure' object has no attribute 'title'
AttributeError: 'Figure' object has no attribute 'title'

